[2023-07-17 08:18:21,998] {taskinstance.py:1159} INFO - Dependencies all met for <TaskInstance: my_airflow_task.my_task manual__2023-07-17T08:18:20.613063+00:00 [queued]>
[2023-07-17 08:18:22,005] {taskinstance.py:1159} INFO - Dependencies all met for <TaskInstance: my_airflow_task.my_task manual__2023-07-17T08:18:20.613063+00:00 [queued]>
[2023-07-17 08:18:22,005] {taskinstance.py:1356} INFO - 
--------------------------------------------------------------------------------
[2023-07-17 08:18:22,005] {taskinstance.py:1357} INFO - Starting attempt 1 of 1
[2023-07-17 08:18:22,005] {taskinstance.py:1358} INFO - 
--------------------------------------------------------------------------------
[2023-07-17 08:18:22,019] {taskinstance.py:1377} INFO - Executing <Task(PythonOperator): my_task> on 2023-07-17 08:18:20.613063+00:00
[2023-07-17 08:18:22,023] {standard_task_runner.py:52} INFO - Started process 4437 to run task
[2023-07-17 08:18:22,025] {standard_task_runner.py:79} INFO - Running: ['***', 'tasks', 'run', 'my_***_task', 'my_task', 'manual__2023-07-17T08:18:20.613063+00:00', '--job-id', '227', '--raw', '--subdir', 'DAGS_FOLDER/read_csv.py', '--cfg-path', '/tmp/tmpfee10_r5', '--error-file', '/tmp/tmplz79ghsi']
[2023-07-17 08:18:22,026] {standard_task_runner.py:80} INFO - Job 227: Subtask my_task
[2023-07-17 08:18:22,076] {task_command.py:369} INFO - Running <TaskInstance: my_airflow_task.my_task manual__2023-07-17T08:18:20.613063+00:00 [running]> on host 938e71f84edd
[2023-07-17 08:18:22,148] {taskinstance.py:1571} INFO - Exporting the following env vars:
AIRFLOW_CTX_DAG_OWNER=***
AIRFLOW_CTX_DAG_ID=my_***_task
AIRFLOW_CTX_TASK_ID=my_task
AIRFLOW_CTX_EXECUTION_DATE=2023-07-17T08:18:20.613063+00:00
AIRFLOW_CTX_TRY_NUMBER=1
AIRFLOW_CTX_DAG_RUN_ID=manual__2023-07-17T08:18:20.613063+00:00
[2023-07-17 08:18:22,149] {taskinstance.py:1889} ERROR - Task failed with exception
Traceback (most recent call last):
  File "/home/airflow/.local/lib/python3.7/site-packages/airflow/operators/python.py", line 171, in execute
    return_value = self.execute_callable()
  File "/home/airflow/.local/lib/python3.7/site-packages/airflow/operators/python.py", line 189, in execute_callable
    return self.python_callable(*self.op_args, **self.op_kwargs)
  File "/opt/airflow/dags/read_csv.py", line 25, in insert_raw_data
    mysql_aunt = connect_mysql()
  File "/opt/airflow/dags/read_csv.py", line 10, in connect_mysql
    engine = create_engine('mysql+pymysql://root:mysql@localhost:3307/data_lake')
  File "<string>", line 2, in create_engine
  File "/home/airflow/.local/lib/python3.7/site-packages/sqlalchemy/util/deprecations.py", line 298, in warned
    return fn(*args, **kwargs)
  File "/home/airflow/.local/lib/python3.7/site-packages/sqlalchemy/engine/create.py", line 548, in create_engine
    dbapi = dialect_cls.dbapi(**dbapi_args)
  File "/home/airflow/.local/lib/python3.7/site-packages/sqlalchemy/dialects/mysql/pymysql.py", line 59, in dbapi
    return __import__("pymysql")
ModuleNotFoundError: No module named 'pymysql'
[2023-07-17 08:18:22,158] {taskinstance.py:1400} INFO - Marking task as FAILED. dag_id=my_***_task, task_id=my_task, execution_date=20230717T081820, start_date=20230717T081821, end_date=20230717T081822
[2023-07-17 08:18:22,168] {standard_task_runner.py:97} ERROR - Failed to execute job 227 for task my_task (No module named 'pymysql'; 4437)
[2023-07-17 08:18:22,197] {local_task_job.py:156} INFO - Task exited with return code 1
[2023-07-17 08:18:22,235] {local_task_job.py:273} INFO - 0 downstream tasks scheduled from follow-on schedule check
