[2023-07-31 06:11:23,734] {taskinstance.py:1159} INFO - Dependencies all met for <TaskInstance: show_table_data.get_data_from_api_insert_to_db manual__2023-07-31T06:11:23.110684+00:00 [queued]>
[2023-07-31 06:11:23,741] {taskinstance.py:1159} INFO - Dependencies all met for <TaskInstance: show_table_data.get_data_from_api_insert_to_db manual__2023-07-31T06:11:23.110684+00:00 [queued]>
[2023-07-31 06:11:23,741] {taskinstance.py:1356} INFO - 
--------------------------------------------------------------------------------
[2023-07-31 06:11:23,741] {taskinstance.py:1357} INFO - Starting attempt 1 of 2
[2023-07-31 06:11:23,741] {taskinstance.py:1358} INFO - 
--------------------------------------------------------------------------------
[2023-07-31 06:11:23,756] {taskinstance.py:1377} INFO - Executing <Task(PythonOperator): get_data_from_api_insert_to_db> on 2023-07-31 06:11:23.110684+00:00
[2023-07-31 06:11:23,760] {standard_task_runner.py:52} INFO - Started process 1325 to run task
[2023-07-31 06:11:23,763] {standard_task_runner.py:79} INFO - Running: ['***', 'tasks', 'run', 'show_table_data', 'get_data_from_api_insert_to_db', 'manual__2023-07-31T06:11:23.110684+00:00', '--job-id', '350', '--raw', '--subdir', 'DAGS_FOLDER/simple_dag_connection.py', '--cfg-path', '/tmp/tmp8j5cplb9', '--error-file', '/tmp/tmpup47rumx']
[2023-07-31 06:11:23,764] {standard_task_runner.py:80} INFO - Job 350: Subtask get_data_from_api_insert_to_db
[2023-07-31 06:11:23,814] {task_command.py:369} INFO - Running <TaskInstance: show_table_data.get_data_from_api_insert_to_db manual__2023-07-31T06:11:23.110684+00:00 [running]> on host 2cb2fe2d8275
[2023-07-31 06:11:23,886] {taskinstance.py:1571} INFO - Exporting the following env vars:
AIRFLOW_CTX_DAG_OWNER=***
AIRFLOW_CTX_DAG_ID=show_table_data
AIRFLOW_CTX_TASK_ID=get_data_from_api_insert_to_db
AIRFLOW_CTX_EXECUTION_DATE=2023-07-31T06:11:23.110684+00:00
AIRFLOW_CTX_TRY_NUMBER=1
AIRFLOW_CTX_DAG_RUN_ID=manual__2023-07-31T06:11:23.110684+00:00
[2023-07-31 06:11:24,014] {logging_mixin.py:115} INFO - connect engine ***
[2023-07-31 06:11:24,014] {logging_mixin.py:115} INFO - connect engine *** succes
[2023-07-31 06:11:24,022] {taskinstance.py:1889} ERROR - Task failed with exception
Traceback (most recent call last):
  File "/home/airflow/.local/lib/python3.7/site-packages/airflow/operators/python.py", line 171, in execute
    return_value = self.execute_callable()
  File "/home/airflow/.local/lib/python3.7/site-packages/airflow/operators/python.py", line 189, in execute_callable
    return self.python_callable(*self.op_args, **self.op_kwargs)
  File "/opt/airflow/dags/package/insert_data_db.py", line 21, in insert_raw_data
    data = get_data()
  File "/opt/airflow/dags/package/insert_data_db.py", line 11, in get_data
    url = Variable.get("url_covid")
  File "/home/airflow/.local/lib/python3.7/site-packages/airflow/models/variable.py", line 138, in get
    raise KeyError(f'Variable {key} does not exist')
KeyError: 'Variable url_covid does not exist'
[2023-07-31 06:11:24,030] {taskinstance.py:1400} INFO - Marking task as UP_FOR_RETRY. dag_id=show_table_data, task_id=get_data_from_api_insert_to_db, execution_date=20230731T061123, start_date=20230731T061123, end_date=20230731T061124
[2023-07-31 06:11:24,041] {standard_task_runner.py:97} ERROR - Failed to execute job 350 for task get_data_from_api_insert_to_db ('Variable url_covid does not exist'; 1325)
[2023-07-31 06:11:24,055] {local_task_job.py:156} INFO - Task exited with return code 1
[2023-07-31 06:11:24,085] {local_task_job.py:273} INFO - 0 downstream tasks scheduled from follow-on schedule check
