[2023-06-24 04:13:07,659] {taskinstance.py:1159} INFO - Dependencies all met for <TaskInstance: sample_connection.python_callable scheduled__2023-06-22T23:00:00+00:00 [queued]>
[2023-06-24 04:13:07,669] {taskinstance.py:1159} INFO - Dependencies all met for <TaskInstance: sample_connection.python_callable scheduled__2023-06-22T23:00:00+00:00 [queued]>
[2023-06-24 04:13:07,669] {taskinstance.py:1356} INFO - 
--------------------------------------------------------------------------------
[2023-06-24 04:13:07,669] {taskinstance.py:1357} INFO - Starting attempt 1 of 1
[2023-06-24 04:13:07,669] {taskinstance.py:1358} INFO - 
--------------------------------------------------------------------------------
[2023-06-24 04:13:07,686] {taskinstance.py:1377} INFO - Executing <Task(PythonOperator): python_callable> on 2023-06-22 23:00:00+00:00
[2023-06-24 04:13:07,691] {standard_task_runner.py:52} INFO - Started process 416 to run task
[2023-06-24 04:13:07,694] {standard_task_runner.py:79} INFO - Running: ['***', 'tasks', 'run', 'sample_connection', 'python_callable', 'scheduled__2023-06-22T23:00:00+00:00', '--job-id', '2', '--raw', '--subdir', 'DAGS_FOLDER/sample_connection.py', '--cfg-path', '/tmp/tmp1exjj89x', '--error-file', '/tmp/tmpfkp3dmha']
[2023-06-24 04:13:07,695] {standard_task_runner.py:80} INFO - Job 2: Subtask python_callable
[2023-06-24 04:13:07,750] {task_command.py:369} INFO - Running <TaskInstance: sample_connection.python_callable scheduled__2023-06-22T23:00:00+00:00 [running]> on host 36e9483e82ad
[2023-06-24 04:13:07,826] {taskinstance.py:1571} INFO - Exporting the following env vars:
AIRFLOW_CTX_DAG_OWNER=***
AIRFLOW_CTX_DAG_ID=sample_connection
AIRFLOW_CTX_TASK_ID=python_callable
AIRFLOW_CTX_EXECUTION_DATE=2023-06-22T23:00:00+00:00
AIRFLOW_CTX_TRY_NUMBER=1
AIRFLOW_CTX_DAG_RUN_ID=scheduled__2023-06-22T23:00:00+00:00
[2023-06-24 04:13:07,847] {taskinstance.py:1889} ERROR - Task failed with exception
Traceback (most recent call last):
  File "/home/airflow/.local/lib/python3.7/site-packages/airflow/operators/python.py", line 171, in execute
    return_value = self.execute_callable()
  File "/home/airflow/.local/lib/python3.7/site-packages/airflow/operators/python.py", line 189, in execute_callable
    return self.python_callable(*self.op_args, **self.op_kwargs)
  File "/opt/airflow/dags/sample_connection.py", line 27, in python_callable
    conn = BaseHook.get_connection('pg-conn')
  File "/home/airflow/.local/lib/python3.7/site-packages/airflow/hooks/base.py", line 67, in get_connection
    conn = Connection.get_connection_from_secrets(conn_id)
  File "/home/airflow/.local/lib/python3.7/site-packages/airflow/models/connection.py", line 430, in get_connection_from_secrets
    raise AirflowNotFoundException(f"The conn_id `{conn_id}` isn't defined")
airflow.exceptions.AirflowNotFoundException: The conn_id `pg-conn` isn't defined
[2023-06-24 04:13:07,851] {taskinstance.py:1400} INFO - Marking task as FAILED. dag_id=sample_connection, task_id=python_callable, execution_date=20230622T230000, start_date=20230624T041307, end_date=20230624T041307
[2023-06-24 04:13:07,863] {standard_task_runner.py:97} ERROR - Failed to execute job 2 for task python_callable (The conn_id `pg-conn` isn't defined; 416)
[2023-06-24 04:13:07,906] {local_task_job.py:156} INFO - Task exited with return code 1
[2023-06-24 04:13:07,947] {local_task_job.py:273} INFO - 0 downstream tasks scheduled from follow-on schedule check
[2023-06-24 04:21:59,445] {taskinstance.py:1159} INFO - Dependencies all met for <TaskInstance: sample_connection.python_callable scheduled__2023-06-22T23:00:00+00:00 [queued]>
[2023-06-24 04:21:59,456] {taskinstance.py:1159} INFO - Dependencies all met for <TaskInstance: sample_connection.python_callable scheduled__2023-06-22T23:00:00+00:00 [queued]>
[2023-06-24 04:21:59,457] {taskinstance.py:1356} INFO - 
--------------------------------------------------------------------------------
[2023-06-24 04:21:59,457] {taskinstance.py:1357} INFO - Starting attempt 1 of 1
[2023-06-24 04:21:59,457] {taskinstance.py:1358} INFO - 
--------------------------------------------------------------------------------
[2023-06-24 04:21:59,473] {taskinstance.py:1377} INFO - Executing <Task(PythonOperator): python_callable> on 2023-06-22 23:00:00+00:00
[2023-06-24 04:21:59,479] {standard_task_runner.py:52} INFO - Started process 623 to run task
[2023-06-24 04:21:59,482] {standard_task_runner.py:79} INFO - Running: ['***', 'tasks', 'run', 'sample_connection', 'python_callable', 'scheduled__2023-06-22T23:00:00+00:00', '--job-id', '6', '--raw', '--subdir', 'DAGS_FOLDER/sample_connection.py', '--cfg-path', '/tmp/tmpu5c91m_y', '--error-file', '/tmp/tmpg1dnk2an']
[2023-06-24 04:21:59,483] {standard_task_runner.py:80} INFO - Job 6: Subtask python_callable
[2023-06-24 04:21:59,552] {task_command.py:369} INFO - Running <TaskInstance: sample_connection.python_callable scheduled__2023-06-22T23:00:00+00:00 [running]> on host 36e9483e82ad
[2023-06-24 04:21:59,652] {taskinstance.py:1571} INFO - Exporting the following env vars:
AIRFLOW_CTX_DAG_OWNER=***
AIRFLOW_CTX_DAG_ID=sample_connection
AIRFLOW_CTX_TASK_ID=python_callable
AIRFLOW_CTX_EXECUTION_DATE=2023-06-22T23:00:00+00:00
AIRFLOW_CTX_TRY_NUMBER=1
AIRFLOW_CTX_DAG_RUN_ID=scheduled__2023-06-22T23:00:00+00:00
[2023-06-24 04:21:59,664] {base.py:68} INFO - Using connection ID 'pg-conn-andhika' for task execution.
[2023-06-24 04:21:59,679] {logging_mixin.py:115} INFO - [INFO] Can't connect PostgreSQL postgres
[2023-06-24 04:21:59,679] {logging_mixin.py:115} INFO - connection to server at "103.105.197.96", port 5431 failed: Connection refused
	Is the server running on that host and accepting TCP/IP connections?
[2023-06-24 04:21:59,679] {taskinstance.py:1889} ERROR - Task failed with exception
Traceback (most recent call last):
  File "/home/airflow/.local/lib/python3.7/site-packages/airflow/operators/python.py", line 171, in execute
    return_value = self.execute_callable()
  File "/home/airflow/.local/lib/python3.7/site-packages/airflow/operators/python.py", line 189, in execute_callable
    return self.python_callable(*self.op_args, **self.op_kwargs)
  File "/opt/airflow/dags/sample_connection.py", line 35, in python_callable
    conn, engine = psql_conn(conf, 'postgres')
TypeError: cannot unpack non-iterable NoneType object
[2023-06-24 04:21:59,691] {taskinstance.py:1400} INFO - Marking task as FAILED. dag_id=sample_connection, task_id=python_callable, execution_date=20230622T230000, start_date=20230624T042159, end_date=20230624T042159
[2023-06-24 04:21:59,700] {standard_task_runner.py:97} ERROR - Failed to execute job 6 for task python_callable (cannot unpack non-iterable NoneType object; 623)
[2023-06-24 04:21:59,734] {local_task_job.py:156} INFO - Task exited with return code 1
[2023-06-24 04:21:59,772] {local_task_job.py:273} INFO - 0 downstream tasks scheduled from follow-on schedule check
[2023-06-24 04:27:42,841] {taskinstance.py:1159} INFO - Dependencies all met for <TaskInstance: sample_connection.python_callable scheduled__2023-06-22T23:00:00+00:00 [queued]>
[2023-06-24 04:27:42,851] {taskinstance.py:1159} INFO - Dependencies all met for <TaskInstance: sample_connection.python_callable scheduled__2023-06-22T23:00:00+00:00 [queued]>
[2023-06-24 04:27:42,851] {taskinstance.py:1356} INFO - 
--------------------------------------------------------------------------------
[2023-06-24 04:27:42,851] {taskinstance.py:1357} INFO - Starting attempt 1 of 1
[2023-06-24 04:27:42,851] {taskinstance.py:1358} INFO - 
--------------------------------------------------------------------------------
[2023-06-24 04:27:42,867] {taskinstance.py:1377} INFO - Executing <Task(PythonOperator): python_callable> on 2023-06-22 23:00:00+00:00
[2023-06-24 04:27:42,873] {standard_task_runner.py:52} INFO - Started process 759 to run task
[2023-06-24 04:27:42,876] {standard_task_runner.py:79} INFO - Running: ['***', 'tasks', 'run', 'sample_connection', 'python_callable', 'scheduled__2023-06-22T23:00:00+00:00', '--job-id', '9', '--raw', '--subdir', 'DAGS_FOLDER/sample_connection.py', '--cfg-path', '/tmp/tmpb4htec3l', '--error-file', '/tmp/tmpg6l8y71c']
[2023-06-24 04:27:42,877] {standard_task_runner.py:80} INFO - Job 9: Subtask python_callable
[2023-06-24 04:27:42,932] {task_command.py:369} INFO - Running <TaskInstance: sample_connection.python_callable scheduled__2023-06-22T23:00:00+00:00 [running]> on host 36e9483e82ad
[2023-06-24 04:27:43,028] {taskinstance.py:1571} INFO - Exporting the following env vars:
AIRFLOW_CTX_DAG_OWNER=***
AIRFLOW_CTX_DAG_ID=sample_connection
AIRFLOW_CTX_TASK_ID=python_callable
AIRFLOW_CTX_EXECUTION_DATE=2023-06-22T23:00:00+00:00
AIRFLOW_CTX_TRY_NUMBER=1
AIRFLOW_CTX_DAG_RUN_ID=scheduled__2023-06-22T23:00:00+00:00
[2023-06-24 04:27:43,041] {base.py:68} INFO - Using connection ID 'pg-conn' for task execution.
[2023-06-24 04:27:43,049] {logging_mixin.py:115} INFO - [INFO] Can't connect PostgreSQL postgres
[2023-06-24 04:27:43,049] {logging_mixin.py:115} INFO - connection to server at "103.105.197.96", port 5431 failed: Connection refused
	Is the server running on that host and accepting TCP/IP connections?
[2023-06-24 04:27:43,049] {taskinstance.py:1889} ERROR - Task failed with exception
Traceback (most recent call last):
  File "/home/airflow/.local/lib/python3.7/site-packages/airflow/operators/python.py", line 171, in execute
    return_value = self.execute_callable()
  File "/home/airflow/.local/lib/python3.7/site-packages/airflow/operators/python.py", line 189, in execute_callable
    return self.python_callable(*self.op_args, **self.op_kwargs)
  File "/opt/airflow/dags/sample_connection.py", line 35, in python_callable
    conn, engine = psql_conn(conf, 'postgres')
TypeError: cannot unpack non-iterable NoneType object
[2023-06-24 04:27:43,058] {taskinstance.py:1400} INFO - Marking task as FAILED. dag_id=sample_connection, task_id=python_callable, execution_date=20230622T230000, start_date=20230624T042742, end_date=20230624T042743
[2023-06-24 04:27:43,068] {standard_task_runner.py:97} ERROR - Failed to execute job 9 for task python_callable (cannot unpack non-iterable NoneType object; 759)
[2023-06-24 04:27:43,088] {local_task_job.py:156} INFO - Task exited with return code 1
[2023-06-24 04:27:43,123] {local_task_job.py:273} INFO - 0 downstream tasks scheduled from follow-on schedule check
