[2023-07-28 16:07:54,156] {taskinstance.py:1159} INFO - Dependencies all met for <TaskInstance: dag_test.read_data manual__2023-07-28T16:07:09.354701+00:00 [queued]>
[2023-07-28 16:07:54,166] {taskinstance.py:1159} INFO - Dependencies all met for <TaskInstance: dag_test.read_data manual__2023-07-28T16:07:09.354701+00:00 [queued]>
[2023-07-28 16:07:54,166] {taskinstance.py:1356} INFO - 
--------------------------------------------------------------------------------
[2023-07-28 16:07:54,166] {taskinstance.py:1357} INFO - Starting attempt 1 of 1
[2023-07-28 16:07:54,166] {taskinstance.py:1358} INFO - 
--------------------------------------------------------------------------------
[2023-07-28 16:07:54,178] {taskinstance.py:1377} INFO - Executing <Task(PythonOperator): read_data> on 2023-07-28 16:07:09.354701+00:00
[2023-07-28 16:07:54,183] {standard_task_runner.py:52} INFO - Started process 2678 to run task
[2023-07-28 16:07:54,186] {standard_task_runner.py:79} INFO - Running: ['***', 'tasks', 'run', 'dag_test', 'read_data', 'manual__2023-07-28T16:07:09.354701+00:00', '--job-id', '297', '--raw', '--subdir', 'DAGS_FOLDER/simple_dag_connection.py', '--cfg-path', '/tmp/tmp8t3zpbp1', '--error-file', '/tmp/tmpj85ualev']
[2023-07-28 16:07:54,187] {standard_task_runner.py:80} INFO - Job 297: Subtask read_data
[2023-07-28 16:07:54,237] {task_command.py:369} INFO - Running <TaskInstance: dag_test.read_data manual__2023-07-28T16:07:09.354701+00:00 [running]> on host ebe3e165ffca
[2023-07-28 16:07:54,316] {taskinstance.py:1571} INFO - Exporting the following env vars:
AIRFLOW_CTX_DAG_OWNER=***
AIRFLOW_CTX_DAG_ID=dag_test
AIRFLOW_CTX_TASK_ID=read_data
AIRFLOW_CTX_EXECUTION_DATE=2023-07-28T16:07:09.354701+00:00
AIRFLOW_CTX_TRY_NUMBER=1
AIRFLOW_CTX_DAG_RUN_ID=manual__2023-07-28T16:07:09.354701+00:00
[2023-07-28 16:07:54,330] {logging_mixin.py:115} INFO - connect engine Postgresql
[2023-07-28 16:07:54,330] {logging_mixin.py:115} INFO - connect engine Postgresql succes
[2023-07-28 16:07:54,331] {taskinstance.py:1889} ERROR - Task failed with exception
Traceback (most recent call last):
  File "/home/airflow/.local/lib/python3.7/site-packages/airflow/operators/python.py", line 171, in execute
    return_value = self.execute_callable()
  File "/home/airflow/.local/lib/python3.7/site-packages/airflow/operators/python.py", line 189, in execute_callable
    return self.python_callable(*self.op_args, **self.op_kwargs)
  File "/opt/airflow/dags/simple_dag_connection.py", line 12, in cek_data_postgres
    df_data = pd.read_sql_query(data, con=mysql_aunt)
  File "/home/airflow/.local/lib/python3.7/site-packages/pandas/io/sql.py", line 443, in read_sql_query
    dtype=dtype,
  File "/home/airflow/.local/lib/python3.7/site-packages/pandas/io/sql.py", line 2116, in read_query
    cursor = self.execute(*args)
  File "/home/airflow/.local/lib/python3.7/site-packages/pandas/io/sql.py", line 2054, in execute
    cur = self.con.cursor()
AttributeError: 'NoneType' object has no attribute 'cursor'
[2023-07-28 16:07:54,339] {taskinstance.py:1400} INFO - Marking task as FAILED. dag_id=dag_test, task_id=read_data, execution_date=20230728T160709, start_date=20230728T160754, end_date=20230728T160754
[2023-07-28 16:07:54,350] {standard_task_runner.py:97} ERROR - Failed to execute job 297 for task read_data ('NoneType' object has no attribute 'cursor'; 2678)
[2023-07-28 16:07:54,358] {local_task_job.py:156} INFO - Task exited with return code 1
[2023-07-28 16:07:54,399] {local_task_job.py:273} INFO - 0 downstream tasks scheduled from follow-on schedule check
