[2023-07-30 15:57:59,783] {taskinstance.py:1159} INFO - Dependencies all met for <TaskInstance: show_table_data.show_table_data manual__2023-07-30T15:57:59.579725+00:00 [queued]>
[2023-07-30 15:57:59,799] {taskinstance.py:1159} INFO - Dependencies all met for <TaskInstance: show_table_data.show_table_data manual__2023-07-30T15:57:59.579725+00:00 [queued]>
[2023-07-30 15:57:59,800] {taskinstance.py:1356} INFO - 
--------------------------------------------------------------------------------
[2023-07-30 15:57:59,800] {taskinstance.py:1357} INFO - Starting attempt 1 of 2
[2023-07-30 15:57:59,800] {taskinstance.py:1358} INFO - 
--------------------------------------------------------------------------------
[2023-07-30 15:57:59,826] {taskinstance.py:1377} INFO - Executing <Task(PythonOperator): show_table_data> on 2023-07-30 15:57:59.579725+00:00
[2023-07-30 15:57:59,832] {standard_task_runner.py:52} INFO - Started process 1281 to run task
[2023-07-30 15:57:59,836] {standard_task_runner.py:79} INFO - Running: ['***', 'tasks', 'run', 'show_table_data', 'show_table_data', 'manual__2023-07-30T15:57:59.579725+00:00', '--job-id', '336', '--raw', '--subdir', 'DAGS_FOLDER/simple_dag_connection.py', '--cfg-path', '/tmp/tmp0juyh73v', '--error-file', '/tmp/tmpzjzd2_60']
[2023-07-30 15:57:59,837] {standard_task_runner.py:80} INFO - Job 336: Subtask show_table_data
[2023-07-30 15:57:59,900] {task_command.py:369} INFO - Running <TaskInstance: show_table_data.show_table_data manual__2023-07-30T15:57:59.579725+00:00 [running]> on host 0981bc456e01
[2023-07-30 15:57:59,980] {taskinstance.py:1571} INFO - Exporting the following env vars:
AIRFLOW_CTX_DAG_OWNER=***
AIRFLOW_CTX_DAG_ID=show_table_data
AIRFLOW_CTX_TASK_ID=show_table_data
AIRFLOW_CTX_EXECUTION_DATE=2023-07-30T15:57:59.579725+00:00
AIRFLOW_CTX_TRY_NUMBER=1
AIRFLOW_CTX_DAG_RUN_ID=manual__2023-07-30T15:57:59.579725+00:00
[2023-07-30 15:58:00,001] {taskinstance.py:1889} ERROR - Task failed with exception
Traceback (most recent call last):
  File "/home/airflow/.local/lib/python3.7/site-packages/airflow/operators/python.py", line 171, in execute
    return_value = self.execute_callable()
  File "/home/airflow/.local/lib/python3.7/site-packages/airflow/operators/python.py", line 189, in execute_callable
    return self.python_callable(*self.op_args, **self.op_kwargs)
  File "/opt/airflow/dags/simple_dag_connection.py", line 32, in show_table_data
    postgres_conn = Connection.get_connection_from_secrets(postgres_conn_id)
  File "/home/airflow/.local/lib/python3.7/site-packages/airflow/models/connection.py", line 430, in get_connection_from_secrets
    raise AirflowNotFoundException(f"The conn_id `{conn_id}` isn't defined")
airflow.exceptions.AirflowNotFoundException: The conn_id `your_postgres_connection_id` isn't defined
[2023-07-30 15:58:00,004] {taskinstance.py:1400} INFO - Marking task as UP_FOR_RETRY. dag_id=show_table_data, task_id=show_table_data, execution_date=20230730T155759, start_date=20230730T155759, end_date=20230730T155800
[2023-07-30 15:58:00,017] {standard_task_runner.py:97} ERROR - Failed to execute job 336 for task show_table_data (The conn_id `your_postgres_connection_id` isn't defined; 1281)
[2023-07-30 15:58:00,047] {local_task_job.py:156} INFO - Task exited with return code 1
[2023-07-30 15:58:00,078] {local_task_job.py:273} INFO - 0 downstream tasks scheduled from follow-on schedule check
