[2023-07-30 15:05:55,851] {taskinstance.py:1159} INFO - Dependencies all met for <TaskInstance: dag_test.read_data manual__2023-07-30T15:04:57.967263+00:00 [queued]>
[2023-07-30 15:05:55,866] {taskinstance.py:1159} INFO - Dependencies all met for <TaskInstance: dag_test.read_data manual__2023-07-30T15:04:57.967263+00:00 [queued]>
[2023-07-30 15:05:55,866] {taskinstance.py:1356} INFO - 
--------------------------------------------------------------------------------
[2023-07-30 15:05:55,867] {taskinstance.py:1357} INFO - Starting attempt 2 of 2
[2023-07-30 15:05:55,867] {taskinstance.py:1358} INFO - 
--------------------------------------------------------------------------------
[2023-07-30 15:05:55,882] {taskinstance.py:1377} INFO - Executing <Task(PythonOperator): read_data> on 2023-07-30 15:04:57.967263+00:00
[2023-07-30 15:05:55,905] {standard_task_runner.py:52} INFO - Started process 1862 to run task
[2023-07-30 15:05:55,908] {standard_task_runner.py:79} INFO - Running: ['***', 'tasks', 'run', 'dag_test', 'read_data', 'manual__2023-07-30T15:04:57.967263+00:00', '--job-id', '327', '--raw', '--subdir', 'DAGS_FOLDER/simple_dag_connection.py', '--cfg-path', '/tmp/tmpm7l0lbu4', '--error-file', '/tmp/tmpkvtbnsga']
[2023-07-30 15:05:55,909] {standard_task_runner.py:80} INFO - Job 327: Subtask read_data
[2023-07-30 15:05:55,968] {task_command.py:369} INFO - Running <TaskInstance: dag_test.read_data manual__2023-07-30T15:04:57.967263+00:00 [running]> on host c58846761b0c
[2023-07-30 15:05:56,050] {taskinstance.py:1571} INFO - Exporting the following env vars:
AIRFLOW_CTX_DAG_OWNER=***
AIRFLOW_CTX_DAG_ID=dag_test
AIRFLOW_CTX_TASK_ID=read_data
AIRFLOW_CTX_EXECUTION_DATE=2023-07-30T15:04:57.967263+00:00
AIRFLOW_CTX_TRY_NUMBER=2
AIRFLOW_CTX_DAG_RUN_ID=manual__2023-07-30T15:04:57.967263+00:00
[2023-07-30 15:05:56,066] {logging_mixin.py:115} INFO - connect engine Postgresql
[2023-07-30 15:05:56,066] {logging_mixin.py:115} INFO - connect engine Postgresql berhasil
[2023-07-30 15:05:56,067] {taskinstance.py:1889} ERROR - Task failed with exception
Traceback (most recent call last):
  File "/home/airflow/.local/lib/python3.7/site-packages/airflow/operators/python.py", line 171, in execute
    return_value = self.execute_callable()
  File "/home/airflow/.local/lib/python3.7/site-packages/airflow/operators/python.py", line 189, in execute_callable
    return self.python_callable(*self.op_args, **self.op_kwargs)
  File "/opt/airflow/dags/simple_dag_connection.py", line 12, in cek_data_postgres
    df_data = pd.read_sql(data, con=mysql_aunt)
  File "/home/airflow/.local/lib/python3.7/site-packages/pandas/io/sql.py", line 608, in read_sql
    chunksize=chunksize,
  File "/home/airflow/.local/lib/python3.7/site-packages/pandas/io/sql.py", line 2116, in read_query
    cursor = self.execute(*args)
  File "/home/airflow/.local/lib/python3.7/site-packages/pandas/io/sql.py", line 2054, in execute
    cur = self.con.cursor()
AttributeError: 'NoneType' object has no attribute 'cursor'
[2023-07-30 15:05:56,074] {taskinstance.py:1400} INFO - Marking task as FAILED. dag_id=dag_test, task_id=read_data, execution_date=20230730T150457, start_date=20230730T150555, end_date=20230730T150556
[2023-07-30 15:05:56,083] {standard_task_runner.py:97} ERROR - Failed to execute job 327 for task read_data ('NoneType' object has no attribute 'cursor'; 1862)
[2023-07-30 15:05:56,120] {local_task_job.py:156} INFO - Task exited with return code 1
[2023-07-30 15:05:56,166] {local_task_job.py:273} INFO - 0 downstream tasks scheduled from follow-on schedule check
