[2023-07-30 15:06:47,373] {taskinstance.py:1159} INFO - Dependencies all met for <TaskInstance: dag_test.read_data manual__2023-07-30T15:04:57.967263+00:00 [queued]>
[2023-07-30 15:06:47,385] {taskinstance.py:1159} INFO - Dependencies all met for <TaskInstance: dag_test.read_data manual__2023-07-30T15:04:57.967263+00:00 [queued]>
[2023-07-30 15:06:47,385] {taskinstance.py:1356} INFO - 
--------------------------------------------------------------------------------
[2023-07-30 15:06:47,385] {taskinstance.py:1357} INFO - Starting attempt 3 of 3
[2023-07-30 15:06:47,385] {taskinstance.py:1358} INFO - 
--------------------------------------------------------------------------------
[2023-07-30 15:06:47,404] {taskinstance.py:1377} INFO - Executing <Task(PythonOperator): read_data> on 2023-07-30 15:04:57.967263+00:00
[2023-07-30 15:06:47,409] {standard_task_runner.py:52} INFO - Started process 1936 to run task
[2023-07-30 15:06:47,412] {standard_task_runner.py:79} INFO - Running: ['***', 'tasks', 'run', 'dag_test', 'read_data', 'manual__2023-07-30T15:04:57.967263+00:00', '--job-id', '328', '--raw', '--subdir', 'DAGS_FOLDER/simple_dag_connection.py', '--cfg-path', '/tmp/tmptsc9c3f2', '--error-file', '/tmp/tmp_5m86i7s']
[2023-07-30 15:06:47,413] {standard_task_runner.py:80} INFO - Job 328: Subtask read_data
[2023-07-30 15:06:47,465] {task_command.py:369} INFO - Running <TaskInstance: dag_test.read_data manual__2023-07-30T15:04:57.967263+00:00 [running]> on host c58846761b0c
[2023-07-30 15:06:47,538] {taskinstance.py:1571} INFO - Exporting the following env vars:
AIRFLOW_CTX_DAG_OWNER=***
AIRFLOW_CTX_DAG_ID=dag_test
AIRFLOW_CTX_TASK_ID=read_data
AIRFLOW_CTX_EXECUTION_DATE=2023-07-30T15:04:57.967263+00:00
AIRFLOW_CTX_TRY_NUMBER=3
AIRFLOW_CTX_DAG_RUN_ID=manual__2023-07-30T15:04:57.967263+00:00
[2023-07-30 15:06:47,551] {logging_mixin.py:115} INFO - connect engine Postgresql
[2023-07-30 15:06:47,551] {logging_mixin.py:115} INFO - connect engine Postgresql berhasil
[2023-07-30 15:06:47,551] {taskinstance.py:1889} ERROR - Task failed with exception
Traceback (most recent call last):
  File "/home/airflow/.local/lib/python3.7/site-packages/airflow/operators/python.py", line 171, in execute
    return_value = self.execute_callable()
  File "/home/airflow/.local/lib/python3.7/site-packages/airflow/operators/python.py", line 189, in execute_callable
    return self.python_callable(*self.op_args, **self.op_kwargs)
  File "/opt/airflow/dags/simple_dag_connection.py", line 12, in cek_data_postgres
    df_data = pd.read_sql(data, con=mysql_aunt)
  File "/home/airflow/.local/lib/python3.7/site-packages/pandas/io/sql.py", line 608, in read_sql
    chunksize=chunksize,
  File "/home/airflow/.local/lib/python3.7/site-packages/pandas/io/sql.py", line 2116, in read_query
    cursor = self.execute(*args)
  File "/home/airflow/.local/lib/python3.7/site-packages/pandas/io/sql.py", line 2054, in execute
    cur = self.con.cursor()
AttributeError: 'NoneType' object has no attribute 'cursor'
[2023-07-30 15:06:47,560] {taskinstance.py:1400} INFO - Marking task as FAILED. dag_id=dag_test, task_id=read_data, execution_date=20230730T150457, start_date=20230730T150647, end_date=20230730T150647
[2023-07-30 15:06:47,570] {standard_task_runner.py:97} ERROR - Failed to execute job 328 for task read_data ('NoneType' object has no attribute 'cursor'; 1936)
[2023-07-30 15:06:47,583] {local_task_job.py:156} INFO - Task exited with return code 1
[2023-07-30 15:06:47,614] {dagrun.py:648} WARNING - Failed to get task '<TaskInstance: dag_test.get_data_postgres manual__2023-07-30T15:04:57.967263+00:00 [removed]>' for dag 'dag_test'. Marking it as removed.
[2023-07-30 15:06:47,624] {local_task_job.py:273} INFO - 0 downstream tasks scheduled from follow-on schedule check
