[2023-07-30 15:04:59,784] {taskinstance.py:1159} INFO - Dependencies all met for <TaskInstance: dag_test.read_data manual__2023-07-30T15:04:57.967263+00:00 [queued]>
[2023-07-30 15:04:59,792] {taskinstance.py:1159} INFO - Dependencies all met for <TaskInstance: dag_test.read_data manual__2023-07-30T15:04:57.967263+00:00 [queued]>
[2023-07-30 15:04:59,792] {taskinstance.py:1356} INFO - 
--------------------------------------------------------------------------------
[2023-07-30 15:04:59,792] {taskinstance.py:1357} INFO - Starting attempt 1 of 1
[2023-07-30 15:04:59,792] {taskinstance.py:1358} INFO - 
--------------------------------------------------------------------------------
[2023-07-30 15:04:59,806] {taskinstance.py:1377} INFO - Executing <Task(PythonOperator): read_data> on 2023-07-30 15:04:57.967263+00:00
[2023-07-30 15:04:59,811] {standard_task_runner.py:52} INFO - Started process 1787 to run task
[2023-07-30 15:04:59,814] {standard_task_runner.py:79} INFO - Running: ['***', 'tasks', 'run', 'dag_test', 'read_data', 'manual__2023-07-30T15:04:57.967263+00:00', '--job-id', '326', '--raw', '--subdir', 'DAGS_FOLDER/simple_dag_connection.py', '--cfg-path', '/tmp/tmpv6h1c_28', '--error-file', '/tmp/tmp58i311yu']
[2023-07-30 15:04:59,815] {standard_task_runner.py:80} INFO - Job 326: Subtask read_data
[2023-07-30 15:04:59,866] {task_command.py:369} INFO - Running <TaskInstance: dag_test.read_data manual__2023-07-30T15:04:57.967263+00:00 [running]> on host c58846761b0c
[2023-07-30 15:04:59,936] {taskinstance.py:1571} INFO - Exporting the following env vars:
AIRFLOW_CTX_DAG_OWNER=***
AIRFLOW_CTX_DAG_ID=dag_test
AIRFLOW_CTX_TASK_ID=read_data
AIRFLOW_CTX_EXECUTION_DATE=2023-07-30T15:04:57.967263+00:00
AIRFLOW_CTX_TRY_NUMBER=1
AIRFLOW_CTX_DAG_RUN_ID=manual__2023-07-30T15:04:57.967263+00:00
[2023-07-30 15:04:59,937] {logging_mixin.py:115} INFO - can't connect postgresql
[2023-07-30 15:04:59,937] {logging_mixin.py:115} INFO - 'Connection' object is not subscriptable
[2023-07-30 15:04:59,937] {taskinstance.py:1889} ERROR - Task failed with exception
Traceback (most recent call last):
  File "/home/airflow/.local/lib/python3.7/site-packages/airflow/operators/python.py", line 171, in execute
    return_value = self.execute_callable()
  File "/home/airflow/.local/lib/python3.7/site-packages/airflow/operators/python.py", line 189, in execute_callable
    return self.python_callable(*self.op_args, **self.op_kwargs)
  File "/opt/airflow/dags/simple_dag_connection.py", line 11, in cek_data_postgres
    curr = conn.cursor()
AttributeError: 'NoneType' object has no attribute 'cursor'
[2023-07-30 15:04:59,946] {taskinstance.py:1400} INFO - Marking task as FAILED. dag_id=dag_test, task_id=read_data, execution_date=20230730T150457, start_date=20230730T150459, end_date=20230730T150459
[2023-07-30 15:04:59,955] {standard_task_runner.py:97} ERROR - Failed to execute job 326 for task read_data ('NoneType' object has no attribute 'cursor'; 1787)
[2023-07-30 15:04:59,986] {local_task_job.py:156} INFO - Task exited with return code 1
[2023-07-30 15:05:00,035] {local_task_job.py:273} INFO - 0 downstream tasks scheduled from follow-on schedule check
