[2023-07-30 14:58:09,668] {taskinstance.py:1159} INFO - Dependencies all met for <TaskInstance: dag_test.read_data manual__2023-07-30T14:43:46.795465+00:00 [queued]>
[2023-07-30 14:58:09,678] {taskinstance.py:1159} INFO - Dependencies all met for <TaskInstance: dag_test.read_data manual__2023-07-30T14:43:46.795465+00:00 [queued]>
[2023-07-30 14:58:09,678] {taskinstance.py:1356} INFO - 
--------------------------------------------------------------------------------
[2023-07-30 14:58:09,678] {taskinstance.py:1357} INFO - Starting attempt 4 of 4
[2023-07-30 14:58:09,678] {taskinstance.py:1358} INFO - 
--------------------------------------------------------------------------------
[2023-07-30 14:58:09,691] {taskinstance.py:1377} INFO - Executing <Task(PythonOperator): read_data> on 2023-07-30 14:43:46.795465+00:00
[2023-07-30 14:58:09,695] {standard_task_runner.py:52} INFO - Started process 1343 to run task
[2023-07-30 14:58:09,698] {standard_task_runner.py:79} INFO - Running: ['***', 'tasks', 'run', 'dag_test', 'read_data', 'manual__2023-07-30T14:43:46.795465+00:00', '--job-id', '321', '--raw', '--subdir', 'DAGS_FOLDER/simple_dag_connection.py', '--cfg-path', '/tmp/tmpo4ktoda3', '--error-file', '/tmp/tmpdf46xgn8']
[2023-07-30 14:58:09,699] {standard_task_runner.py:80} INFO - Job 321: Subtask read_data
[2023-07-30 14:58:09,747] {task_command.py:369} INFO - Running <TaskInstance: dag_test.read_data manual__2023-07-30T14:43:46.795465+00:00 [running]> on host c58846761b0c
[2023-07-30 14:58:09,817] {taskinstance.py:1571} INFO - Exporting the following env vars:
AIRFLOW_CTX_DAG_OWNER=***
AIRFLOW_CTX_DAG_ID=dag_test
AIRFLOW_CTX_TASK_ID=read_data
AIRFLOW_CTX_EXECUTION_DATE=2023-07-30T14:43:46.795465+00:00
AIRFLOW_CTX_TRY_NUMBER=4
AIRFLOW_CTX_DAG_RUN_ID=manual__2023-07-30T14:43:46.795465+00:00
[2023-07-30 14:58:09,818] {logging_mixin.py:115} INFO - can't connect postgresql
[2023-07-30 14:58:09,818] {logging_mixin.py:115} INFO - 'Connection' object is not subscriptable
[2023-07-30 14:58:09,819] {taskinstance.py:1889} ERROR - Task failed with exception
Traceback (most recent call last):
  File "/home/airflow/.local/lib/python3.7/site-packages/airflow/operators/python.py", line 171, in execute
    return_value = self.execute_callable()
  File "/home/airflow/.local/lib/python3.7/site-packages/airflow/operators/python.py", line 189, in execute_callable
    return self.python_callable(*self.op_args, **self.op_kwargs)
  File "/opt/airflow/dags/simple_dag_connection.py", line 11, in cek_data_postgres
    curr = conn.cursor()
AttributeError: 'NoneType' object has no attribute 'cursor'
[2023-07-30 14:58:09,827] {taskinstance.py:1400} INFO - Marking task as FAILED. dag_id=dag_test, task_id=read_data, execution_date=20230730T144346, start_date=20230730T145809, end_date=20230730T145809
[2023-07-30 14:58:09,836] {standard_task_runner.py:97} ERROR - Failed to execute job 321 for task read_data ('NoneType' object has no attribute 'cursor'; 1343)
[2023-07-30 14:58:09,870] {local_task_job.py:156} INFO - Task exited with return code 1
[2023-07-30 14:58:09,926] {local_task_job.py:273} INFO - 0 downstream tasks scheduled from follow-on schedule check
