[2023-07-30 14:59:12,277] {taskinstance.py:1159} INFO - Dependencies all met for <TaskInstance: dag_test.read_data manual__2023-07-30T14:43:46.795465+00:00 [queued]>
[2023-07-30 14:59:12,285] {taskinstance.py:1159} INFO - Dependencies all met for <TaskInstance: dag_test.read_data manual__2023-07-30T14:43:46.795465+00:00 [queued]>
[2023-07-30 14:59:12,285] {taskinstance.py:1356} INFO - 
--------------------------------------------------------------------------------
[2023-07-30 14:59:12,285] {taskinstance.py:1357} INFO - Starting attempt 5 of 5
[2023-07-30 14:59:12,285] {taskinstance.py:1358} INFO - 
--------------------------------------------------------------------------------
[2023-07-30 14:59:12,298] {taskinstance.py:1377} INFO - Executing <Task(PythonOperator): read_data> on 2023-07-30 14:43:46.795465+00:00
[2023-07-30 14:59:12,303] {standard_task_runner.py:52} INFO - Started process 1412 to run task
[2023-07-30 14:59:12,306] {standard_task_runner.py:79} INFO - Running: ['***', 'tasks', 'run', 'dag_test', 'read_data', 'manual__2023-07-30T14:43:46.795465+00:00', '--job-id', '322', '--raw', '--subdir', 'DAGS_FOLDER/simple_dag_connection.py', '--cfg-path', '/tmp/tmpg4aosg9b', '--error-file', '/tmp/tmpqlqseqx_']
[2023-07-30 14:59:12,307] {standard_task_runner.py:80} INFO - Job 322: Subtask read_data
[2023-07-30 14:59:12,357] {task_command.py:369} INFO - Running <TaskInstance: dag_test.read_data manual__2023-07-30T14:43:46.795465+00:00 [running]> on host c58846761b0c
[2023-07-30 14:59:12,428] {taskinstance.py:1571} INFO - Exporting the following env vars:
AIRFLOW_CTX_DAG_OWNER=***
AIRFLOW_CTX_DAG_ID=dag_test
AIRFLOW_CTX_TASK_ID=read_data
AIRFLOW_CTX_EXECUTION_DATE=2023-07-30T14:43:46.795465+00:00
AIRFLOW_CTX_TRY_NUMBER=5
AIRFLOW_CTX_DAG_RUN_ID=manual__2023-07-30T14:43:46.795465+00:00
[2023-07-30 14:59:12,429] {logging_mixin.py:115} INFO - can't connect postgresql
[2023-07-30 14:59:12,429] {logging_mixin.py:115} INFO - 'Connection' object is not subscriptable
[2023-07-30 14:59:12,429] {taskinstance.py:1889} ERROR - Task failed with exception
Traceback (most recent call last):
  File "/home/airflow/.local/lib/python3.7/site-packages/airflow/operators/python.py", line 171, in execute
    return_value = self.execute_callable()
  File "/home/airflow/.local/lib/python3.7/site-packages/airflow/operators/python.py", line 189, in execute_callable
    return self.python_callable(*self.op_args, **self.op_kwargs)
  File "/opt/airflow/dags/simple_dag_connection.py", line 11, in cek_data_postgres
    curr = conn.cursor()
AttributeError: 'NoneType' object has no attribute 'cursor'
[2023-07-30 14:59:12,437] {taskinstance.py:1400} INFO - Marking task as FAILED. dag_id=dag_test, task_id=read_data, execution_date=20230730T144346, start_date=20230730T145912, end_date=20230730T145912
[2023-07-30 14:59:12,447] {standard_task_runner.py:97} ERROR - Failed to execute job 322 for task read_data ('NoneType' object has no attribute 'cursor'; 1412)
[2023-07-30 14:59:12,477] {local_task_job.py:156} INFO - Task exited with return code 1
[2023-07-30 14:59:12,533] {local_task_job.py:273} INFO - 0 downstream tasks scheduled from follow-on schedule check
