[2023-07-30 15:02:12,480] {taskinstance.py:1159} INFO - Dependencies all met for <TaskInstance: dag_test.read_data manual__2023-07-30T14:43:46.795465+00:00 [queued]>
[2023-07-30 15:02:12,491] {taskinstance.py:1159} INFO - Dependencies all met for <TaskInstance: dag_test.read_data manual__2023-07-30T14:43:46.795465+00:00 [queued]>
[2023-07-30 15:02:12,491] {taskinstance.py:1356} INFO - 
--------------------------------------------------------------------------------
[2023-07-30 15:02:12,492] {taskinstance.py:1357} INFO - Starting attempt 7 of 7
[2023-07-30 15:02:12,492] {taskinstance.py:1358} INFO - 
--------------------------------------------------------------------------------
[2023-07-30 15:02:12,507] {taskinstance.py:1377} INFO - Executing <Task(PythonOperator): read_data> on 2023-07-30 14:43:46.795465+00:00
[2023-07-30 15:02:12,512] {standard_task_runner.py:52} INFO - Started process 1616 to run task
[2023-07-30 15:02:12,515] {standard_task_runner.py:79} INFO - Running: ['***', 'tasks', 'run', 'dag_test', 'read_data', 'manual__2023-07-30T14:43:46.795465+00:00', '--job-id', '324', '--raw', '--subdir', 'DAGS_FOLDER/simple_dag_connection.py', '--cfg-path', '/tmp/tmpnpis4f94', '--error-file', '/tmp/tmpazbdfj8n']
[2023-07-30 15:02:12,516] {standard_task_runner.py:80} INFO - Job 324: Subtask read_data
[2023-07-30 15:02:12,576] {task_command.py:369} INFO - Running <TaskInstance: dag_test.read_data manual__2023-07-30T14:43:46.795465+00:00 [running]> on host c58846761b0c
[2023-07-30 15:02:12,663] {taskinstance.py:1571} INFO - Exporting the following env vars:
AIRFLOW_CTX_DAG_OWNER=***
AIRFLOW_CTX_DAG_ID=dag_test
AIRFLOW_CTX_TASK_ID=read_data
AIRFLOW_CTX_EXECUTION_DATE=2023-07-30T14:43:46.795465+00:00
AIRFLOW_CTX_TRY_NUMBER=7
AIRFLOW_CTX_DAG_RUN_ID=manual__2023-07-30T14:43:46.795465+00:00
[2023-07-30 15:02:12,664] {logging_mixin.py:115} INFO - can't connect postgresql
[2023-07-30 15:02:12,664] {logging_mixin.py:115} INFO - 'Connection' object is not subscriptable
[2023-07-30 15:02:12,664] {taskinstance.py:1889} ERROR - Task failed with exception
Traceback (most recent call last):
  File "/home/airflow/.local/lib/python3.7/site-packages/airflow/operators/python.py", line 171, in execute
    return_value = self.execute_callable()
  File "/home/airflow/.local/lib/python3.7/site-packages/airflow/operators/python.py", line 189, in execute_callable
    return self.python_callable(*self.op_args, **self.op_kwargs)
  File "/opt/airflow/dags/simple_dag_connection.py", line 11, in cek_data_postgres
    curr = conn.cursor()
AttributeError: 'NoneType' object has no attribute 'cursor'
[2023-07-30 15:02:12,673] {taskinstance.py:1400} INFO - Marking task as FAILED. dag_id=dag_test, task_id=read_data, execution_date=20230730T144346, start_date=20230730T150212, end_date=20230730T150212
[2023-07-30 15:02:12,682] {standard_task_runner.py:97} ERROR - Failed to execute job 324 for task read_data ('NoneType' object has no attribute 'cursor'; 1616)
[2023-07-30 15:02:12,727] {local_task_job.py:156} INFO - Task exited with return code 1
[2023-07-30 15:02:12,835] {local_task_job.py:273} INFO - 0 downstream tasks scheduled from follow-on schedule check
